  + Exception Group Traceback (most recent call last):
  |   File "/…/v8serialize/test/jstypes/_v8_traceback_error_fixtures.py", line 84, in call_and_capture_tbe
  |     fn()
  |   File "/…/v8serialize/test/jstypes/_v8_traceback_error_fixtures.py", line 64, in raise_sub_group_with_context
  |     raise ExceptionGroup("This is fine", [fail1, fail2])
  | ExceptionGroup: This is fine (2 sub-exceptions)
  +-+---------------- 1 ----------------
    | Exception Group Traceback (most recent call last):
    |   File "/…/v8serialize/test/jstypes/_v8_traceback_error_fixtures.py", line 55, in raise_sub_group_with_context
    |     self.raise_group_with_context()
    |   File "/…/v8serialize/test/jstypes/_v8_traceback_error_fixtures.py", line 51, in raise_group_with_context
    |     raise ExceptionGroup("Everything went wrong", [fail1, fail2])
    | ExceptionGroup: Everything went wrong (2 sub-exceptions)
    +-+---------------- 1 ----------------
      | Traceback (most recent call last):
      |   File "/…/v8serialize/test/jstypes/_v8_traceback_error_fixtures.py", line 76, in failing_operation_with_context
      |     self.failing_operation()
      |   File "/…/v8serialize/test/jstypes/_v8_traceback_error_fixtures.py", line 68, in failing_operation
      |     raise ValueError("Unable to do the thing")
      | ValueError: Unable to do the thing
      | 
      | During handling of the above exception, another exception occurred:
      | 
      | Traceback (most recent call last):
      |   File "/…/v8serialize/test/jstypes/_v8_traceback_error_fixtures.py", line 42, in raise_group_with_context
      |     self.failing_operation_with_context()
      |   File "/…/v8serialize/test/jstypes/_v8_traceback_error_fixtures.py", line 78, in failing_operation_with_context
      |     e.missing_attribute  # type: ignore[attr-defined]
      |     ^^^^^^^^^^^^^^^^^^^
      | AttributeError: 'ValueError' object has no attribute 'missing_attribute'
      +---------------- 2 ----------------
      | Traceback (most recent call last):
      |   File "/…/v8serialize/test/jstypes/_v8_traceback_error_fixtures.py", line 47, in raise_group_with_context
      |     self.failing_operation2()
      |   File "/…/v8serialize/test/jstypes/_v8_traceback_error_fixtures.py", line 72, in failing_operation2
      |     raise TypeError("Expected an Apple but received an Orange")
      | TypeError: Expected an Apple but received an Orange
      +------------------------------------
    +---------------- 2 ----------------
    | Exception Group Traceback (most recent call last):
    |   File "/…/v8serialize/test/jstypes/_v8_traceback_error_fixtures.py", line 60, in raise_sub_group_with_context
    |     self.raise_group()
    |   File "/…/v8serialize/test/jstypes/_v8_traceback_error_fixtures.py", line 24, in raise_group
    |     raise ExceptionGroup("Everything went wrong", [fail1, fail2])
    | ExceptionGroup: Everything went wrong (2 sub-exceptions)
    +-+---------------- 1 ----------------
      | Traceback (most recent call last):
      |   File "/…/v8serialize/test/jstypes/_v8_traceback_error_fixtures.py", line 15, in raise_group
      |     self.failing_operation()
      |   File "/…/v8serialize/test/jstypes/_v8_traceback_error_fixtures.py", line 68, in failing_operation
      |     raise ValueError("Unable to do the thing")
      | ValueError: Unable to do the thing
      +---------------- 2 ----------------
      | Traceback (most recent call last):
      |   File "/…/v8serialize/test/jstypes/_v8_traceback_error_fixtures.py", line 20, in raise_group
      |     self.failing_operation2()
      |   File "/…/v8serialize/test/jstypes/_v8_traceback_error_fixtures.py", line 72, in failing_operation2
      |     raise TypeError("Expected an Apple but received an Orange")
      | TypeError: Expected an Apple but received an Orange
      +------------------------------------
