  + Exception Group Traceback (most recent call last):
  |   File "/…/v8serialize/test/jstypes/_v8_traceback_error_fixtures.py", line 94, in call_and_capture_tbe
  |     fn()
  |   File "/…/v8serialize/test/jstypes/_v8_traceback_error_fixtures.py", line 61, in raise_group_with_context
  |     raise ExceptionGroup("Everything went wrong", [fail1, fail2])
  | ExceptionGroup: Everything went wrong (2 sub-exceptions)
  +-+---------------- 1 ----------------
    | Traceback (most recent call last):
    |   File "/…/v8serialize/test/jstypes/_v8_traceback_error_fixtures.py", line 86, in failing_operation_with_context
    |     self.failing_operation()
    |   File "/…/v8serialize/test/jstypes/_v8_traceback_error_fixtures.py", line 78, in failing_operation
    |     raise ValueError("Unable to do the thing")
    | ValueError: Unable to do the thing
    | 
    | During handling of the above exception, another exception occurred:
    | 
    | Traceback (most recent call last):
    |   File "/…/v8serialize/test/jstypes/_v8_traceback_error_fixtures.py", line 52, in raise_group_with_context
    |     self.failing_operation_with_context()
    |   File "/…/v8serialize/test/jstypes/_v8_traceback_error_fixtures.py", line 88, in failing_operation_with_context
    |     e.missing_attribute.foo()  # type: ignore[attr-defined]
    |     ^^^^^^^^^^^^^^^^^^^
    | AttributeError: 'ValueError' object has no attribute 'missing_attribute'
    +---------------- 2 ----------------
    | Traceback (most recent call last):
    |   File "/…/v8serialize/test/jstypes/_v8_traceback_error_fixtures.py", line 57, in raise_group_with_context
    |     self.failing_operation2()
    |   File "/…/v8serialize/test/jstypes/_v8_traceback_error_fixtures.py", line 82, in failing_operation2
    |     raise TypeError("Expected an Apple but received an Orange")
    | TypeError: Expected an Apple but received an Orange
    +------------------------------------
